<?xml version="1.0"?>
<robot name="robot" xmlns:xacro="http://www.ros.org/wiki/xacro">
  <!-- Switch for Ignition vs Classic -->
  <xacro:arg name="is_ignition" default="true"/>

  <!-- Define Blue material -->
  <material name="Blue">
    <color rgba="0 0 1 1"/>
  </material>

  <!-- Root link -->
  <link name="base_link">
    <inertial>
      <origin xyz="0 0 0.04" rpy="0 0 0"/>
      <mass value="0.82573504"/>
      <inertia
        ixx="0.022124416" ixy="-0.00012294101" ixz="0.00034938785"
        iyy="0.021193702"  iyz="-0.000050120904"
        izz="0.020064271"/>
    </inertial>
    <visual>
      <origin xyz="0 0 0" rpy="0 0 0"/>
      <geometry>
        <box size="0.20 0.14 0.08"/>
      </geometry>
      <material name="Blue"/>
    </visual>
    <collision>
      <origin xyz="0 0 0" rpy="0 0 0"/>
      <geometry>
        <box size="0.20 0.14 0.08"/>
      </geometry>
    </collision>
  </link>

  <!-- Right wheel -->
  <link name="wheel_right_link">
    <inertial>
      <origin xyz="0 -0.014 0" rpy="0 0 0"/>
      <mass value="0.05300861"/>
      <inertia ixx="1.88e-05" ixy="0" ixz="0"
               iyy="3.12e-05" iyz="0" izz="1.88e-05"/>
    </inertial>
    <visual>
      <origin xyz="0 0 0" rpy="1.57 0 0"/>
      <geometry>
        <sphere radius="0.033"/>
      </geometry>
    </visual>
    <collision>
      <origin xyz="0 -0.015 0" rpy="1.57 0 0"/>
      <geometry>
        <sphere radius="0.033"/>
      </geometry>
    </collision>
  </link>
  <joint name="wheel_right_joint" type="continuous">
    <origin xyz="0 -0.07011 0" rpy="0 0 0"/>
    <parent link="base_link"/>
    <child link="wheel_right_link"/>
    <axis xyz="0 1 0"/>
  </joint>

  <!-- Left wheel -->
  <link name="wheel_left_link">
    <inertial>
      <origin xyz="0 0.014 0" rpy="0 0 0"/>
      <mass value="0.05300860"/>
      <inertia ixx="1.88e-05" ixy="0" ixz="0"
               iyy="3.12e-05" iyz="0" izz="1.88e-05"/>
    </inertial>
    <visual>
      <origin xyz="0 0 0" rpy="-1.57 0 0"/>
      <geometry>
        <sphere radius="0.033"/>
      </geometry>
    </visual>
    <collision>
      <origin xyz="0 0.015 0" rpy="-1.57 0 0"/>
      <geometry>
        <sphere radius="0.033"/>
      </geometry>
    </collision>
  </link>
  <joint name="wheel_left_joint" type="continuous">
    <origin xyz="0 0.07011 0" rpy="0 0 0"/>
    <parent link="base_link"/>
    <child link="wheel_left_link"/>
    <axis xyz="0 1 0"/>
  </joint>

  <!-- Front caster -->
  <link name="caster_front_link">
    <inertial>
      <origin xyz="0 0 0.00219" rpy="0 0 0"/>
      <mass value="1.44e-06"/>
      <inertia ixx="7.23e-11" ixy="0" ixz="0"
               iyy="3.87e-11" iyz="0" izz="1.01e-10"/>
    </inertial>
    <visual>
      <origin xyz="0 0 0" rpy="0 0 0"/>
      <geometry>
        <sphere radius="0.005"/>
      </geometry>
    </visual>
    <collision>
      <origin xyz="0 0 0" rpy="0 0 0"/>
      <geometry>
        <sphere radius="0.005"/>
      </geometry>
    </collision>
  </link>
  <joint name="caster_front_joint" type="fixed">
    <origin xyz="0.04755 0 -0.0275" rpy="0 0 0"/>
    <parent link="base_link"/>
    <child link="caster_front_link"/>
  </joint>

  <!-- Rear caster -->
  <link name="caster_rear_link">
    <inertial>
      <origin xyz="0 0 0.00219" rpy="0 0 0"/>
      <mass value="1.44e-06"/>
      <inertia ixx="7.23e-11" ixy="0" ixz="0"
               iyy="3.87e-11" iyz="0" izz="1.01e-10"/>
    </inertial>
    <visual>
      <origin xyz="0 0 0" rpy="0 0 0"/>
      <geometry>
        <sphere radius="0.005"/>
      </geometry>
    </visual>
    <collision>
      <origin xyz="0 0 0" rpy="0 0 0"/>
      <geometry>
        <sphere radius="0.005"/>
      </geometry>
    </collision>
  </link>
  <joint name="caster_rear_joint" type="fixed">
    <origin xyz="-0.04755 0 -0.0275" rpy="0 0 0"/>
    <parent link="base_link"/>
    <child link="caster_rear_link"/>
  </joint>

</robot>
